Workbook

Sheet README
A1: Uepaki — Seller Acquisition Command Center
A3: The single operating tracker for seller acquisition. It supersedes the trackers inside the First 25/100/300 lists, the Segmentation workbook KPI sheet and the Activation Checklist tracker for day-to-day use (those remain reference material).
A4: PROSPECTS is pre-filled with the red-team-corrected "Golden 300 v2" (Waves 0–2) plus blank rows for Wave −1 friendly testers, existing-seller reactivation, inbound and peer introductions. One row per professional. Never duplicate a professional.
A5: Brown headers = pre-filled from the database (read-only). Dark headers = enter data (dates as yyyy-mm-dd; dropdowns where offered). Green headers = calculated — do not type.
A6: No phone numbers, emails or WhatsApp links are stored. Resolve the verified business route from the master database by Prospect ID at outreach time and re-check it is still published.
A7: Contactable ≠ consent. 0 prospects have opted in to marketing. WhatsApp only after the professional invites it; AiSensy templates only after a recorded opt-in (column "WhatsApp opt-in").
A8: ACTIVATED = Approval date + Profile complete date + Listing live date + Payout details date + Standing OK = Y.
A9: All thresholds in SETTINGS are diagnostic TEST thresholds — not Uepaki benchmarks. Replace with observed rates after Wave 0–1.
A10: Do not start any campaign while BLOCKERS shows open Critical gates for that campaign.
A11: Sheets: PROSPECTS · CAMPAIGNS · CAMPAIGN_DASHBOARD · KPI_FUNNEL · WEEKLY_COHORTS · BLOCKERS · BUDGET · SETTINGS · LISTS

Sheet SETTINGS
A1: Diagnostic TEST thresholds — not Uepaki benchmarks
A2: Setting | B2: Value | C2: Use
A3: Days after first contact for follow-up 1 | B3: 5 | C3: Next follow-up date
A4: Days after follow-up 1 for final note | B4: 7 | C4: Next follow-up date
A5: Days of silence after sequence before any re-approach | B5: 75 | C5: Next action
A6: Minimum cell size to read a rate | B6: 20 | C6: Dashboards: below this = "Too early"
A7: Reply rate: STOP / rework below | B7: 0.1 | C7: Campaign rule (after ≥ 40 delivered)
A8: Reply rate: SCALE at or above | B8: 0.2 | C8: Campaign rule
A9: Interested → Registered: investigate below | B9: 0.3 | C9: Conversion
A10: Registered → Approved: investigate below | B10: 0.7 | C10: Conversion
A11: Approved → Activated: investigate below | B11: 0.5 | C11: Conversion
A12: Bounce rate: STOP above | B12: 0.05 | C12: Data quality
A13: Opt-out / negative rate: STOP above | B13: 0.02 | C13: Compliance guardrail
A14: Days in a stage before STUCK | B14: 3 | C14: Onboarding alert
A15: Contacts needed before a campaign rule is applied | B15: 40 | C15: Campaign rule

Sheet PROSPECTS
A1: Rank (v2) | B1: Prospect ID | C1: Prospect (name as they use it) | D1: Category | E1: Segment | F1: City | G1: Tier | H1: Priority (OS) | I1: Red-team flags | J1: Recommended channel | K1: Public route reference | L1: Campaign | M1: Channel used | N1: Owner | O1: Contact date | P1: Follow-up 1 sent | Q1: Follow-up 2 sent | R1: Response date | S1: Response type | T1: Interest date | U1: GSTIN status | V1: Registration date | W1: KYC submitted date | X1: Approval date | Y1: Profile complete date | Z1: Listing live date | AA1: Payout details date | AB1: Standing OK (Y/N) | AC1: Transaction date | AD1: Consent: named (Y/N) | AE1: WhatsApp opt-in (Y/N, date) | AF1: Manual next follow-up | AG1: Notes | AH1: Activated | AI1: Activation date | AJ1: Stage | AK1: Next follow-up | AL1: Next action | AM1: Due | AN1: Days in stage | AO1: Alert
A2: 1 | B2: UPK2-FL-172 | C2: Corpora Studio | D2: Fashion & Lifestyle | E2: FL-CONTEMPORARY | F2: Delhi NCR | G2: A | H2: P0 | I2: stockist-listed | J2: Personal 1:1 email from founder/team to published business email | K2: https://corporastudio.in/pages/contact | L2: W0 Pilot | AH2: =IF(AND(B2="",C2=""),"",IF(AND(X2<>"",Y2<>"",Z2<>"",AA2<>"",AB2="Y"),"YES","no")) | AI2: =IF(AH2="YES",MAX(X2,Y2,Z2,AA2),"") | AJ2: =IF(AND(B2="",C2=""),"",IF(OR(S2="Not interested",S2="Opt-out / do not contact"),"X Declined / suppressed",IF(S2="Bounced / undeliverable","X Bounced — research",IF(AC2<>"","13 Transacting",IF(AH2="YES","12 ACTIVATED",IF(Z2<>"","11 Listing live",IF(Y2<>"","10 Profile complete",IF(X2<>"","9 Approved",IF(W2<>"","8 KYC submitted",IF(V2<>"","7 Registered",IF(T2<>"","5 Interested",IF(R2<>"","4 Responded",IF(O2<>"","2 Contacted","1 Not yet contacted"))))))))))))) | AK2: =IF(AF2<>"",AF2,IF(OR(O2="",R2<>"",LEFT(AJ2,1)="X"),"",IF(Q2<>"","",IF(P2<>"",P2+SETTINGS!$B$4,O2+SETTINGS!$B$3)))) | AL2: =IF(AJ2="","",IF(LEFT(AJ2,1)="X","None — do not contact",IF(AJ2="1 Not yet contacted","Verify route today, then send M1",IF(AND(R2="",Q2<>""),"Sequence complete — no contact before "&TEXT(Q2+SETTINGS!$B$5,"yyyy-mm-dd"),IF(AND(R2="",P2<>""),"Send final note (M4)",IF(R2="","Send follow-up (M2)",IF(AJ2="12 ACTIVATED","7-day check-in; consent & referral soft ask",IF(AJ2="13 Transacting","Repeat-activity support","Onboarding: move to next stage (see playbook §6)")))))))) | AM2: =IF(ISNUMBER(AK2),IF(AK2<=TODAY(),"DUE",""),"") | AN2: =IF(COUNT(O2,P2,Q2,R2,T2,V2,W2,X2,Y2,Z2,AA2,AC2)=0,"",TODAY()-MAX(O2,P2,Q2,R2,T2,V2,W2,X2,Y2,Z2,AA2,AC2)) | AO2: =IF(AJ2="","",IF(AND(T2<>"",U2<>"Active (verified)"),"GST: escalate (no tax advice)",IF(AND(IFERROR(VALUE(LEFT(AJ2,2)),0)>=5,AH2<>"YES",ISNUMBER(AN2),AN2>SETTINGS!$B$14),"STUCK in onboarding","")))
A3: 2 | B3: UPK2-FL-200 | C3: Akhl | D3: Fashion & Lifestyle | E3: FL-CONTEMPORARY | F3: Delhi NCR | G3: A | H3: P0 | I3: stockist-listed | J3: Personal 1:1 email from founder/team to published business email | K3: https://www.akhlstudio.com/contact | L3: W0 Pilot | AH3: =IF(AND(B3="",C3=""),"",IF(AND(X3<>"",Y3<>"",Z3<>"",AA3<>"",AB3="Y"),"YES","no")) | AI3: =IF(AH3="YES",MAX(X3,Y3,Z3,AA3),"") | AJ3: =IF(AND(B3="",C3=""),"",IF(OR(S3="Not interested",S3="Opt-out / do not contact"),"X Declined / suppressed",IF(S3="Bounced / undeliverable","X Bounced — research",IF(AC3<>"","13 Transacting",IF(AH3="YES","12 ACTIVATED",IF(Z3<>"","11 Listing live",IF(Y3<>"","10 Profile complete",IF(X3<>"","9 Approved",IF(W3<>"","8 KYC submitted",IF(V3<>"","7 Registered",IF(T3<>"","5 Interested",IF(R3<>"","4 Responded",IF(O3<>"","2 Contacted","1 Not yet contacted"))))))))))))) | AK3: =IF(AF3<>"",AF3,IF(OR(O3="",R3<>"",LEFT(AJ3,1)="X"),"",IF(Q3<>"","",IF(P3<>"",P3+SETTINGS!$B$4,O3+SETTINGS!$B$3)))) | AL3: =IF(AJ3="","",IF(LEFT(AJ3,1)="X","None — do not contact",IF(AJ3="1 Not yet contacted","Verify route today, then send M1",IF(AND(R3="",Q3<>""),"Sequence complete — no contact before "&TEXT(Q3+SETTINGS!$B$5,"yyyy-mm-dd"),IF(AND(R3="",P3<>""),"Send final note (M4)",IF(R3="","Send follow-up (M2)",IF(AJ3="12 ACTIVATED","7-day check-in; consent & referral soft ask",IF(AJ3="13 Transacting","Repeat-activity support","Onboarding: move to next stage (see playbook §6)")))))))) | AM3: =IF(ISNUMBER(AK3),IF(AK3<=TODAY(),"DUE",""),"") | AN3: =IF(COUNT(O3,P3,Q3,R3,T3,V3,W3,X3,Y3,Z3,AA3,AC3)=0,"",TODAY()-MAX(O3,P3,Q3,R3,T3,V3,W3,X3,Y3,Z3,AA3,AC3)) | AO3: =IF(AJ3="","",IF(AND(T3<>"",U3<>"Active (verified)"),"GST: escalate (no tax advice)",IF(AND(IFERROR(VALUE(LEFT(AJ3,2)),0)>=5,AH3<>"YES",ISNUMBER(AN3),AN3>SETTINGS!$B$14),"STUCK in onboarding","")))
A4: 3 | B4: UPK2-FL-173 | C4: Kamaali Couture | D4: Fashion & Lifestyle | E4: FL-CONTEMPORARY | F4: Delhi NCR | G4: B | H4: P0 | I4: stockist-listed | J4: Personal 1:1 email from founder/team to published business email | K4: https://kamaali.in/pages/contact-us-1 | L4: W0 Pilot | AH4: =IF(AND(B4="",C4=""),"",IF(AND(X4<>"",Y4<>"",Z4<>"",AA4<>"",AB4="Y"),"YES","no")) | AI4: =IF(AH4="YES",MAX(X4,Y4,Z4,AA4),"") | AJ4: =IF(AND(B4="",C4=""),"",IF(OR(S4="Not interested",S4="Opt-out / do not contact"),"X Declined / suppressed",IF(S4="Bounced / undeliverable","X Bounced — research",IF(AC4<>"","13 Transacting",IF(AH4="YES","12 ACTIVATED",IF(Z4<>"","11 Listing live",IF(Y4<>"","10 Profile complete",IF(X4<>"","9 Approved",IF(W4<>"","8 KYC submitted",IF(V4<>"","7 Registered",IF(T4<>"","5 Interested",IF(R4<>"","4 Responded",IF(O4<>"","2 Contacted","1 Not yet contacted"))))))))))))) | AK4: =IF(AF4<>"",AF4,IF(OR(O4="",R4<>"",LEFT(AJ4,1)="X"),"",IF(Q4<>"","",IF(P4<>"",P4+SETTINGS!$B$4,O4+SETTINGS!$B$3)))) | AL4: =IF(AJ4="","",IF(LEFT(AJ4,1)="X","None — do not contact",IF(AJ4="1 Not yet contacted","Verify route today, then send M1",IF(AND(R4="",Q4<>""),"Sequence complete — no contact before "&TEXT(Q4+SETTINGS!$B$5,"yyyy-mm-dd"),IF(AND(R4="",P4<>""),"Send final note (M4)",IF(R4="","Send follow-up (M2)",IF(AJ4="12 ACTIVATED","7-day check-in; consent & referral soft ask",IF(AJ4="13 Transacting","Repeat-activity support","Onboarding: move to next stage (see playbook §6)")))))))) | AM4: =IF(ISNUMBER(AK4),IF(AK4<=TODAY(),"DUE",""),"") | AN4: =IF(COUNT(O4,P4,Q4,R4,T4,V4,W4,X4,Y4,Z4,AA4,AC4)=0,"",TODAY()-MAX(O4,P4,Q4,R4,T4,V4,W4,X4,Y4,Z4,AA4,AC4)) | AO4: =IF(AJ4="","",IF(AND(T4<>"",U4<>"Active (verified)"),"GST: escalate (no tax advice)",IF(AND(IFERROR(VALUE(LEFT(AJ4,2)),0)>=5,AH4<>"YES",ISNUMBER(AN4),AN4>SETTINGS!$B$14),"STUCK in onboarding","")))
A5: 4 | B5: UPK2-FL-180 | C5: Ituvana | D5: Fashion & Lifestyle | E5: FL-JEWELLERY | F5: Delhi NCR | G5: B | H5: P0 | I5: stockist-listed | J5: Personal 1:1 email from founder/team to published business email | K5: https://www.ituvana.com/pages/contact-us | L5: W0 Pilot | AH5: =IF(AND(B5="",C5=""),"",IF(AND(X5<>"",Y5<>"",Z5<>"",AA5<>"",AB5="Y"),"YES","no")) | AI5: =IF(AH5="YES",MAX(X5,Y5,Z5,AA5),"") | AJ5: =IF(AND(B5="",C5=""),"",IF(OR(S5="Not interested",S5="Opt-out / do not contact"),"X Declined / suppressed",IF(S5="Bounced / undeliverable","X Bounced — research",IF(AC5<>"","13 Transacting",IF(AH5="YES","12 ACTIVATED",IF(Z5<>"","11 Listing live",IF(Y5<>"","10 Profile complete",IF(X5<>"","9 Approved",IF(W5<>"","8 KYC submitted",IF(V5<>"","7 Registered",IF(T5<>"","5 Interested",IF(R5<>"","4 Responded",IF(O5<>"","2 Contacted","1 Not yet contacted"))))))))))))) | AK5: =IF(AF5<>"",AF5,IF(OR(O5="",R5<>"",LEFT(AJ5,1)="X"),"",IF(Q5<>"","",IF(P5<>"",P5+SETTINGS!$B$4,O5+SETTINGS!$B$3)))) | AL5: =IF(AJ5="","",IF(LEFT(AJ5,1)="X","None — do not contact",IF(AJ5="1 Not yet contacted","Verify route today, then send M1",IF(AND(R5="",Q5<>""),"Sequence complete — no contact before "&TEXT(Q5+SETTINGS!$B$5,"yyyy-mm-dd"),IF(AND(R5="",P5<>""),"Send final note (M4)",IF(R5="","Send follow-up (M2)",IF(AJ5="12 ACTIVATED","7-day check-in; consent & referral soft ask",IF(AJ5="13 Transacting","Repeat-activity support","Onboarding: move to next stage (see playbook §6)")))))))) | AM5: =IF(ISNUMBER(AK5),IF(AK5<=TODAY(),"DUE",""),"") | AN5: =IF(COUNT(O5,P5,Q5,R5,T5,V5,W5,X5,Y5,Z5,AA5,AC5)=0,"",TODAY()-MAX(O5,P5,Q5,R5,T5,V5,W5,X5,Y5,Z5,AA5,AC5)) | AO5: =IF(AJ5="","",IF(AND(T5<>"",U5<>"Active (verified)"),"GST: escalate (no tax advice)",IF(AND(IFERROR(VALUE(LEFT(AJ5,2)),0)>=5,AH5<>"YES",ISNUMBER(AN5),AN5>SETTINGS!$B$14),"STUCK in onboarding","")))
A6: 5 | B6: UPK2-FL-273 | C6: Jigar Mali | D6: Fashion & Lifestyle | E6: FL-OCCASION-BRIDAL | F6: Delhi NCR | G6: A | H6: P0 | I6: stockist-listed | J6: Personal 1:1 email from founder/team to published business email | K6: https://jigarmali.com/pages/contact | L6: W0 Pilot | AH6: =IF(AND(B6="",C6=""),"",IF(AND(X6<>"",Y6<>"",Z6<>"",AA6<>"",AB6="Y"),"YES","no")) | AI6: =IF(AH6="YES",MAX(X6,Y6,Z6,AA6),"") | AJ6: =IF(AND(B6="",C6=""),"",IF(OR(S6="Not interested",S6="Opt-out / do not contact"),"X Declined / suppressed",IF(S6="Bounced / undeliverable","X Bounced — research",IF(AC6<>"","13 Transacting",IF(AH6="YES","12 ACTIVATED",IF(Z6<>"","11 Listing live",IF(Y6<>"","10 Profile complete",IF(X6<>"","9 Approved",IF(W6<>"","8 KYC submitted",IF(V6<>"","7 Registered",IF(T6<>"","5 Interested",IF(R6<>"","4 Responded",IF(O6<>"","2 Contacted","1 Not yet contacted"))))))))))))) | AK6: =IF(AF6<>"",AF6,IF(OR(O6="",R6<>"",LEFT(AJ6,1)="X"),"",IF(Q6<>"","",IF(P6<>"",P6+SETTINGS!$B$4,O6+SETTINGS!$B$3)))) | AL6: =IF(AJ6="","",IF(LEFT(AJ6,1)="X","None — do not contact",IF(AJ6="1 Not yet contacted","Verify route today, then send M1",IF(AND(R6="",Q6<>""),"Sequence complete — no contact before "&TEXT(Q6+SETTINGS!$B$5,"yyyy-mm-dd"),IF(AND(R6="",P6<>""),"Send final note (M4)",IF(R6="","Send follow-up (M2)",IF(AJ6="12 ACTIVATED","7-day check-in; consent & referral soft ask",IF(AJ6="13 Transacting","Repeat-activity support","Onboarding: move to next stage (see playbook §6)")))))))) | AM6: =IF(ISNUMBER(AK6),IF(AK6<=TODAY(),"DUE",""),"") | AN6: =IF(COUNT(O6,P6,Q6,R6,T6,V6,W6,X6,Y6,Z6,AA6,AC6)=0,"",TODAY()-MAX(O6,P6,Q6,R6,T6,V6,W6,X6,Y6,Z6,AA6,AC6)) | AO6: =IF(AJ6="","",IF(AND(T6<>"",U6<>"Active (verified)"),"GST: escalate (no tax advice)",IF(AND(IFERROR(VALUE(LEFT(AJ6,2)),0)>=5,AH6<>"YES",ISNUMBER(AN6),AN6>SETTINGS!$B$14),"STUCK in onboarding","")))
A7: 6 | B7: UPK2-FL-199 | C7: Thee Modern Roots | D7: Fashion & Lifestyle | E7: FL-OCCASION-BRIDAL | F7: Delhi NCR | G7: A | H7: P0 | I7: stockist-listed | J7: Personal 1:1 email from founder/team to published business email | K7: https://theemodernroots.com/pages/contact | L7: W0 Pilot | AH7: =IF(AND(B7="",C7=""),"",IF(AND(X7<>"",Y7<>"",Z7<>"",AA7<>"",AB7="Y"),"YES","no")) | AI7: =IF(AH7="YES",MAX(X7,Y7,Z7,AA7),"") | AJ7: =IF(AND(B7="",C7=""),"",IF(OR(S7="Not interested",S7="Opt-out / do not contact"),"X Declined / suppressed",IF(S7="Bounced / undeliverable","X Bounced — research",IF(AC7<>"","13 Transacting",IF(AH7="YES","12 ACTIVATED",IF(Z7<>"","11 Listing live",IF(Y7<>"","10 Profile complete",IF(X7<>"","9 Approved",IF(W7<>"","8 KYC submitted",IF(V7<>"","7 Registered",IF(T7<>"","5 Interested",IF(R7<>"","4 Responded",IF(O7<>"","2 Contacted","1 Not yet contacted"))))))))))))) | AK7: =IF(AF7<>"",AF7,IF(OR(O7="",R7<>"",LEFT(AJ7,1)="X"),"",IF(Q7<>"","",IF(P7<>"",P7+SETTINGS!$B$4,O7+SETTINGS!$B$3)))) | AL7: =IF(AJ7="","",IF(LEFT(AJ7,1)="X","None — do not contact",IF(AJ7="1 Not yet contacted","Verify route today, then send M1",IF(AND(R7="",Q7<>""),"Sequence complete — no contact before "&TEXT(Q7+SETTINGS!$B$5,"yyyy-mm-dd"),IF(AND(R7="",P7<>""),"Send final note (M4)",IF(R7="","Send follow-up (M2)",IF(AJ7="12 ACTIVATED","7-day check-in; consent & referral soft ask",IF(AJ7="13 Transacting","Repeat-activity support","Onboarding: move to next stage (see playbook §6)")))))))) | AM7: =IF(ISNUMBER(AK7),IF(AK7<=TODAY(),"DUE",""),"") | AN7: =IF(COUNT(O7,P7,Q7,R7,T7,V7,W7,X7,Y7,Z7,AA7,AC7)=0,"",TODAY()-MAX(O7,P7,Q7,R7,T7,V7,W7,X7,Y7,Z7,AA7,AC7)) | AO7: =IF(AJ7="","",IF(AND(T7<>"",U7<>"Active (verified)"),"GST: escalate (no tax advice)",IF(AND(IFERROR(VALUE(LEFT(AJ7,2)),0)>=5,AH7<>"YES",ISNUMBER(AN7),AN7>SETTINGS!$B$14),"STUCK in onboarding","")))
A8: 7 | B8: UPK2-SD-290 | C8: Parman Designs | D8: Space & Design | E8: SD-PRODUCT-MAKER | F8: Delhi NCR | G8: A | H8: P0 | I8: under-discovered | J8: Personal 1:1 email from founder/team to published business email | K8: https://www.parmandesigns.com/ | L8: W0 Pilot | AH8: =IF(AND(B8="",C8=""),"",IF(AND(X8<>"",Y8<>"",Z8<>"",AA8<>"",AB8="Y"),"YES","no")) | AI8: =IF(AH8="YES",MAX(X8,Y8,Z8,AA8),"") | AJ8: =IF(AND(B8="",C8=""),"",IF(OR(S8="Not interested",S8="Opt-out / do not contact"),"X Declined / suppressed",IF(S8="Bounced / undeliverable","X Bounced — research",IF(AC8<>"","13 Transacting",IF(AH8="YES","12 ACTIVATED",IF(Z8<>"","11 Listing live",IF(Y8<>"","10 Profile complete",IF(X8<>"","9 Approved",IF(W8<>"","8 KYC submitted",IF(V8<>"","7 Registered",IF(T8<>"","5 Interested",IF(R8<>"","4 Responded",IF(O8<>"","2 Contacted","1 Not yet contacted"))))))))))))) | AK8: =IF(AF8<>"",AF8,IF(OR(O8="",R8<>"",LEFT(AJ8,1)="X"),"",IF(Q8<>"","",IF(P8<>"",P8+SETTINGS!$B$4,O8+SETTINGS!$B$3)))) | AL8: =IF(AJ8="","",IF(LEFT(AJ8,1)="X","None — do not contact",IF(AJ8="1 Not yet contacted","Verify route today, then send M1",IF(AND(R8="",Q8<>""),"Sequence complete — no contact before "&TEXT(Q8+SETTINGS!$B$5,"yyyy-mm-dd"),IF(AND(R8="",P8<>""),"Send final note (M4)",IF(R8="","Send follow-up (M2)",IF(AJ8="12 ACTIVATED","7-day check-in; consent & referral soft ask",IF(AJ8="13 Transacting","Repeat-activity support","Onboarding: move to next stage (see playbook §6)")))))))) | AM8: =IF(ISNUMBER(AK8),IF(AK8<=TODAY(),"DUE",""),"") | AN8: =IF(COUNT(O8,P8,Q8,R8,T8,V8,W8,X8,Y8,Z8,AA8,AC8)=0,"",TODAY()-MAX(O8,P8,Q8,R8,T8,V8,W8,X8,Y8,Z8,AA8,AC8)) | AO8: =IF(AJ8="","",IF(AND(T8<>"",U8<>"Active (verified)"),"GST: escalate (no tax advice)",IF(AND(IFERROR(VALUE(LEFT(AJ8,2)),0)>=5,AH8<>"YES",ISNUMBER(AN8),AN8>SETTINGS!$B$14),"STUCK in onboarding","")))
A9: 8 | B9: UPK2-SD-292 | C9: Harshita Jhamtani Designs LLP | D9: Space & Design | E9: SD-PRODUCT-MAKER | F9: Mumbai | G9: A | H9: P0 | I9: under-discovered | J9: Personal 1:1 email from founder/team to published business email | K9: https://www.harshitajhamtani.com/ | L9: W0 Pilot | AH9: =IF(AND(B9="",C9=""),"",IF(AND(X9<>"",Y9<>"",Z9<>"",AA9<>"",AB9="Y"),"YES","no")) | AI9: =IF(AH9="YES",MAX(X9,Y9,Z9,AA9),"") | AJ9: =IF(AND(B9="",C9=""),"",IF(OR(S9="Not interested",S9="Opt-out / do not contact"),"X Declined / suppressed",IF(S9="Bounced / undeliverable","X Bounced — research",IF(AC9<>"","13 Transacting",IF(AH9="YES","12 ACTIVATED",IF(Z9<>"","11 Listing live",IF(Y9<>"","10 Profile complete",IF(X9<>"","9 Approved",IF(W9<>"","8 KYC submitted",IF(V9<>"","7 Registered",IF(T9<>"","5 Interested",IF(R9<>"","4 Responded",IF(O9<>"","2 Contacted","1 Not yet contacted"))))))))))))) | AK9: =IF(AF9<>"",AF9,IF(OR(O9="",R9<>"",LEFT(AJ9,1)="X"),"",IF(Q9<>"","",IF(P9<>"",P9+SETTINGS!$B$4,O9+SETTINGS!$B$3)))) | AL9: =IF(AJ9="","",IF(LEFT(AJ9,1)="X","None — do not contact",IF(AJ9="1 Not yet contacted","Verify route today, then send M1",IF(AND(R9="",Q9<>""),"Sequence complete — no contact before "&TEXT(Q9+SETTINGS!$B$5,"yyyy-mm-dd"),IF(AND(R9="",P9<>""),"Send final note (M4)",IF(R9="","Send follow-up (M2)",IF(AJ9="12 ACTIVATED","7-day check-in; consent & referral soft ask",IF(AJ9="13 Transacting","Repeat-activity support","Onboarding: move to next stage (see playbook §6)")))))))) | AM9: =IF(ISNUMBER(AK9),IF(AK9<=TODAY(),"DUE",""),"") | AN9: =IF(COUNT(O9,P9,Q9,R9,T9,V9,W9,X9,Y9,Z9,AA9,AC9)=0,"",TODAY()-MAX(O9,P9,Q9,R9,T9,V9,W9,X9,Y9,Z9,AA9,AC9)) | AO9: =IF(AJ9="","",IF(AND(T9<>"",U9<>"Active (verified)"),"GST: escalate (no tax advice)",IF(AND(IFERROR(VALUE(LEFT(AJ9,2)),0)>=5,AH9<>"YES",ISNUMBER(AN9),AN9>SETTINGS!$B$14),"STUCK in onboarding","")))
A10: 9 | B10: UPK2-SD-291 | C10: LumeHaus | D10: Space & Design | E10: SD-PRODUCT-MAKER | F10: Delhi NCR | G10: A | H10: P0 | I10: under-discovered | J10: Personal 1:1 email from founder/team to published business email | K10: https://lumehaus.in/ | L10: W0 Pilot | AH10: =IF(AND(B10="",C10=""),"",IF(AND(X10<>"",Y10<>"",Z10<>"",AA10<>"",AB10="Y"),"YES","no")) | AI10: =IF(AH10="YES",MAX(X10,Y10,Z10,AA10),"") | AJ10: =IF(AND(B10="",C10=""),"",IF(OR(S10="Not interested",S10="Opt-out / do not contact"),"X Declined / suppressed",IF(S10="Bounced / undeliverable","X Bounced — research",IF(AC10<>"","13 Transacting",IF(AH10="YES","12 ACTIVATED",IF(Z10<>"","11 Listing live",IF(Y10<>"","10 Profile complete",IF(X10<>"","9 Approved",IF(W10<>"","8 KYC submitted",IF(V10<>"","7 Registered",IF(T10<>"","5 Interested",IF(R10<>"","4 Responded",IF(O10<>"","2 Contacted","1 Not yet contacted"))))))))))))) | AK10: =IF(AF10<>"",AF10,IF(OR(O10="",R10<>"",LEFT(AJ10,1)="X"),"",IF(Q10<>"","",IF(P10<>"",P10+SETTINGS!$B$4,O10+SETTINGS!$B$3)))) | AL10: =IF(AJ10="","",IF(LEFT(AJ10,1)="X","None — do not contact",IF(AJ10="1 Not yet contacted","Verify route today, then send M1",IF(AND(R10="",Q10<>""),"Sequence complete — no contact before "&TEXT(Q10+SETTINGS!$B$5,"yyyy-mm-dd"),IF(AND(R10="",P10<>""),"Send final note (M4)",IF(R10="","Send follow-up (M2)",IF(AJ10="12 ACTIVATED","7-day check-in; consent & referral soft ask",IF(AJ10="13 Transacting","Repeat-activity support","Onboarding: move to next stage (see playbook §6)")))))))) | AM10: =IF(ISNUMBER(AK10),IF(AK10<=TODAY(),"DUE",""),"") | AN10: =IF(COUNT(O10,P10,Q10,R10,T10,V10,W10,X10,Y10,Z10,AA10,AC10)=0,"",TODAY()-MAX(O10,P10,Q10,R10,T10,V10,W10,X10,Y10,Z10,AA10,AC10)) | AO10: =IF(AJ10="","",IF(AND(T10<>"",U10<>"Active (verified)"),"GST: escalate (no tax advice)",IF(AND(IFERROR(VALUE(LEFT(AJ10,2)),0)>=5,AH10<>"YES",ISNUMBER(AN10),AN10>SETTINGS!$B$14),"STUCK in onboarding","")))
A11: 10 | B11: UPK2-SD-018 | C11: Saaz Design Studio | D11: Space & Design | E11: SD-ARCHITECTURE | F11: Delhi NCR | G11: A | H11: P0 | I11: under-discovered | J11: Personal 1:1 email from founder/team to published business email | K11: https://www.saazdesignstudio.com/ | L11: W0 Pilot | AH11: =IF(AND(B11="",C11=""),"",IF(AND(X11<>"",Y11<>"",Z11<>"",AA11<>"",AB11="Y"),"YES","no")) | AI11: =IF(AH11="YES",MAX(X11,Y11,Z11,AA11),"") | AJ11: =IF(AND(B11="",C11=""),"",IF(OR(S11="Not interested",S11="Opt-out / do not contact"),"X Declined / suppressed",IF(S11="Bounced / undeliverable","X Bounced — research",IF(AC11<>"","13 Transacting",IF(AH11="YES","12 ACTIVATED",IF(Z11<>"","11 Listing live",IF(Y11<>"","10 Profile complete",IF(X11<>"","9 Approved",IF(W11<>"","8 KYC submitted",IF(V11<>"","7 Registered",IF(T11<>"","5 Interested",IF(R11<>"","4 Responded",IF(O11<>"","2 Contacted","1 Not yet contacted"))))))))))))) | AK11: =IF(AF11<>"",AF11,IF(OR(O11="",R11<>"",LEFT(AJ11,1)="X"),"",IF(Q11<>"","",IF(P11<>"",P11+SETTINGS!$B$4,O11+SETTINGS!$B$3)))) | AL11: =IF(AJ11="","",IF(LEFT(AJ11,1)="X","None — do not contact",IF(AJ11="1 Not yet contacted","Verify route today, then send M1",IF(AND(R11="",Q11<>""),"Sequence complete — no contact before "&TEXT(Q11+SETTINGS!$B$5,"yyyy-mm-dd"),IF(AND(R11="",P11<>""),"Send final note (M4)",IF(R11="","Send follow-up (M2)",IF(AJ11="12 ACTIVATED","7-day check-in; consent & referral soft ask",IF(AJ11="13 Transacting","Repeat-activity support","Onboarding: move to next stage (see playbook §6)")))))))) | AM11: =IF(ISNUMBER(AK11),IF(AK11<=TODAY(),"DUE",""),"") | AN11: =IF(COUNT(O11,P11,Q11,R11,T11,V11,W11,X11,Y11,Z11,AA11,AC11)=0,"",TODAY()-MAX(O11,P11,Q11,R11,T11,V11,W11,X11,Y11,Z11,AA11,AC11)) | AO11: =IF(AJ11="","",IF(AND(T11<>"",U11<>"Active (verified)"),"GST: escalate (no tax advice)",IF(AND(IFERROR(VALUE(LEFT(AJ11,2)),0)>=5,AH11<>"YES",ISNUMBER(AN11),AN11>SETTINGS!$B$14),"STUCK in onboarding","")))
A12: 11 | B12: UPK2-SD-009 | C12: Studio Dot | D12: Space & Design | E12: SD-INTERIOR | F12: Delhi NCR | G12: A | H12: P0 | I12: under-discovered | J12: Personal 1:1 email from founder/team to published business email | K12: https://www.studiodot.co.in/contact | L12: W0 Pilot | AH12: =IF(AND(B12="",C12=""),"",IF(AND(X12<>"",Y12<>"",Z12<>"",AA12<>"",AB12="Y"),"YES","no")) | AI12: =IF(AH12="YES",MAX(X12,Y12,Z12,AA12),"") | AJ12: =IF(AND(B12="",C12=""),"",IF(OR(S12="Not interested",S12="Opt-out / do not contact"),"X Declined / suppressed",IF(S12="Bounced / undeliverable","X Bounced — research",IF(AC12<>"","13 Transacting",IF(AH12="YES","12 ACTIVATED",IF(Z12<>"","11 Listing live",IF(Y12<>"","10 Profile complete",IF(X12<>"","9 Approved",IF(W12<>"","8 KYC submitted",IF(V12<>"","7 Registered",IF(T12<>"","5 Interested",IF(R12<>"","4 Responded",IF(O12<>"","2 Contacted","1 Not yet contacted"))))))))))))) | AK12: =IF(AF12<>"",AF12,IF(OR(O12="",R12<>"",LEFT(AJ12,1)="X"),"",IF(Q12<>"","",IF(P12<>"",P12+SETTINGS!$B$4,O12+SETTINGS!$B$3)))) | AL12: =IF(AJ12="","",IF(LEFT(AJ12,1)="X","None — do not contact",IF(AJ12="1 Not yet contacted","Verify route today, then send M1",IF(AND(R12="",Q12<>""),"Sequence complete — no contact before "&TEXT(Q12+SETTINGS!$B$5,"yyyy-mm-dd"),IF(AND(R12="",P12<>""),"Send final note (M4)",IF(R12="","Send follow-up (M2)",IF(AJ12="12 ACTIVATED","7-day check-in; consent & referral soft ask",IF(AJ12="13 Transacting","Repeat-activity support","Onboarding: move to next stage (see playbook §6)")))))))) | AM12: =IF(ISNUMBER(AK12),IF(AK12<=TODAY(),"DUE",""),"") | AN12: =IF(COUNT(O12,P12,Q12,R12,T12,V12,W12,X12,Y12,Z12,AA12,AC12)=0,"",TODAY()-MAX(O12,P12,Q12,R12,T12,V12,W12,X12,Y12,Z12,AA12,AC12)) | AO12: =IF(AJ12="","",IF(AND(T12<>"",U12<>"Active (verified)"),"GST: escalate (no tax advice)",IF(AND(IFERROR(VALUE(LEFT(AJ12,2)),0)>=5,AH12<>"YES",ISNUMBER(AN12),AN12>SETTINGS!$B$14),"STUCK in onboarding","")))
A13: 12 | B13: UPK2-SD-003 | C13: Navrasa | D13: Space & Design | E13: SD-INTERIOR | F13: Delhi NCR | G13: B | H13: P0 | J13: Personal 1:1 email from founder/team to published business email | K13: https://nav-rasa.com/ | L13: W0 Pilot | AH13: =IF(AND(B13="",C13=""),"",IF(AND(X13<>"",Y13<>"",Z13<>"",AA13<>"",AB13="Y"),"YES","no")) | AI13: =IF(AH13="YES",MAX(X13,Y13,Z13,AA13),"") | AJ13: =IF(AND(B13="",C13=""),"",IF(OR(S13="Not interested",S13="Opt-out / do not contact"),"X Declined / suppressed",IF(S13="Bounced / undeliverable","X Bounced — research",IF(AC13<>"","13 Transacting",IF(AH13="YES","12 ACTIVATED",IF(Z13<>"","11 Listing live",IF(Y13<>"","10 Profile complete",IF(X13<>"","9 Approved",IF(W13<>"","8 KYC submitted",IF(V13<>"","7 Registered",IF(T13<>"","5 Interested",IF(R13<>"","4 Responded",IF(O13<>"","2 Contacted","1 Not yet contacted"))))))))))))) | AK13: =IF(AF13<>"",AF13,IF(OR(O13="",R13<>"",LEFT(AJ13,1)="X"),"",IF(Q13<>"","",IF(P13<>"",P13+SETTINGS!$B$4,O13+SETTINGS!$B$3)))) | AL13: =IF(AJ13="","",IF(LEFT(AJ13,1)="X","None — do not contact",IF(AJ13="1 Not yet contacted","Verify route today, then send M1",IF(AND(R13="",Q13<>""),"Sequence complete — no contact before "&TEXT(Q13+SETTINGS!$B$5,"yyyy-mm-dd"),IF(AND(R13="",P13<>""),"Send final note (M4)",IF(R13="","Send follow-up (M2)",IF(AJ13="12 ACTIVATED","7-day check-in; consent & referral soft ask",IF(AJ13="13 Transacting","Repeat-activity support","Onboarding: move to next stage (see playbook §6)")))))))) | AM13: =IF(ISNUMBER(AK13),IF(AK13<=TODAY(),"DUE",""),"") | AN13: =IF(COUNT(O13,P13,Q13,R13,T13,V13,W13,X13,Y13,Z13,AA13,AC13)=0,"",TODAY()-MAX(O13,P13,Q13,R13,T13,V13,W13,X13,Y13,Z13,AA13,AC13)) | AO13: =IF(AJ13="","",IF(AND(T13<>"",U13<>"Active (verified)"),"GST: escalate (no tax advice)",IF(AND(IFERROR(VALUE(LEFT(AJ13,2)),0)>=5,AH13<>"YES",ISNUMBER(AN13),AN13>SETTINGS!$B$14),"STUCK in onboarding","")))
A14: 13 | B14: UPK2-DV-006 | C14: Inkyhand | D14: Digital & Visual Arts | E14: DV-CALLIGRAPHY-STATIONERY | F14: Delhi NCR | G14: A | H14: P0 | I14: under-discovered | J14: Personal 1:1 email from founder/team to published business email | K14: https://www.inkyhand.com/ | L14: W0 Pilot | AH14: =IF(AND(B14="",C14=""),"",IF(AND(X14<>"",Y14<>"",Z14<>"",AA14<>"",AB14="Y"),"YES","no")) | AI14: =IF(AH14="YES",MAX(X14,Y14,Z14,AA14),"") | AJ14: =IF(AND(B14="",C14=""),"",IF(OR(S14="Not interested",S14="Opt-out / do not contact"),"X Declined / suppressed",IF(S14="Bounced / undeliverable","X Bounced — research",IF(AC14<>"","13 Transacting",IF(AH14="YES","12 ACTIVATED",IF(Z14<>"","11 Listing live",IF(Y14<>"","10 Profile complete",IF(X14<>"","9 Approved",IF(W14<>"","8 KYC submitted",IF(V14<>"","7 Registered",IF(T14<>"","5 Interested",IF(R14<>"","4 Responded",IF(O14<>"","2 Contacted","1 Not yet contacted"))))))))))))) | AK14: =IF(AF14<>"",AF14,IF(OR(O14="",R14<>"",LEFT(AJ14,1)="X"),"",IF(Q14<>"","",IF(P14<>"",P14+SETTINGS!$B$4,O14+SETTINGS!$B$3)))) | AL14: =IF(AJ14="","",IF(LEFT(AJ14,1)="X","None — do not contact",IF(AJ14="1 Not yet contacted","Verify route today, then send M1",IF(AND(R14="",Q14<>""),"Sequence complete — no contact before "&TEXT(Q14+SETTINGS!$B$5,"yyyy-mm-dd"),IF(AND(R14="",P14<>""),"Send final note (M4)",IF(R14="","Send follow-up (M2)",IF(AJ14="12 ACTIVATED","7-day check-in; consent & referral soft ask",IF(AJ14="13 Transacting","Repeat-activity support","Onboarding: move to next stage (see playbook §6)")))))))) | AM14: =IF(ISNUMBER(AK14),IF(AK14<=TODAY(),"DUE",""),"") | AN14: =IF(COUNT(O14,P14,Q14,R14,T14,V14,W14,X14,Y14,Z14,AA14,AC14)=0,"",TODAY()-MAX(O14,P14,Q14,R14,T14,V14,W14,X14,Y14,Z14,AA14,AC14)) | AO14: =IF(AJ14="","",IF(AND(T14<>"",U14<>"Active (verified)"),"GST: escalate (no tax advice)",IF(AND(IFERROR(VALUE(LEFT(AJ14,2)),0)>=5,AH14<>"YES",ISNUMBER(AN14),AN14>SETTINGS!$B$14),"STUCK in onboarding","")))
A15: 14 | B15: UPK2-DV-034 | C15: Presentable | D15: Digital & Visual Arts | E15: DV-DESIGN-STUDIO | F15: Delhi NCR | G15: B | H15: P0 | J15: Personal 1:1 email from founder/team to published business email | K15: https://www.makepresentable.com/contact | L15: W0 Pilot | AH15: =IF(AND(B15="",C15=""),"",IF(AND(X15<>"",Y15<>"",Z15<>"",AA15<>"",AB15="Y"),"YES","no")) | AI15: =IF(AH15="YES",MAX(X15,Y15,Z15,AA15),"") | AJ15: =IF(AND(B15="",C15=""),"",IF(OR(S15="Not interested",S15="Opt-out / do not contact"),"X Declined / suppressed",IF(S15="Bounced / undeliverable","X Bounced — research",IF(AC15<>"","13 Transacting",IF(AH15="YES","12 ACTIVATED",IF(Z15<>"","11 Listing live",IF(Y15<>"","10 Profile complete",IF(X15<>"","9 Approved",IF(W15<>"","8 KYC submitted",IF(V15<>"","7 Registered",IF(T15<>"","5 Interested",IF(R15<>"","4 Responded",IF(O15<>"","2 Contacted","1 Not yet contacted"))))))))))))) | AK15: =IF(AF15<>"",AF15,IF(OR(O15="",R15<>"",LEFT(AJ15,1)="X"),"",IF(Q15<>"","",IF(P15<>"",P15+SETTINGS!$B$4,O15+SETTINGS!$B$3)))) | AL15: =IF(AJ15="","",IF(LEFT(AJ15,1)="X","None — do not contact",IF(AJ15="1 Not yet contacted","Verify route today, then send M1",IF(AND(R15="",Q15<>""),"Sequence complete — no contact before "&TEXT(Q15+SETTINGS!$B$5,"yyyy-mm-dd"),IF(AND(R15="",P15<>""),"Send final note (M4)",IF(R15="","Send follow-up (M2)",IF(AJ15="12 ACTIVATED","7-day check-in; consent & referral soft ask",IF(AJ15="13 Transacting","Repeat-activity support","Onboarding: move to next stage (see playbook §6)")))))))) | AM15: =IF(ISNUMBER(AK15),IF(AK15<=TODAY(),"DUE",""),"") | AN15: =IF(COUNT(O15,P15,Q15,R15,T15,V15,W15,X15,Y15,Z15,AA15,AC15)=0,"",TODAY()-MAX(O15,P15,Q15,R15,T15,V15,W15,X15,Y15,Z15,AA15,AC15)) | AO15: =IF(AJ15="","",IF(AND(T15<>"",U15<>"Active (verified)"),"GST: escalate (no tax advice)",IF(AND(IFERROR(VALUE(LEFT(AJ15,2)),0)>=5,AH15<>"YES",ISNUMBER(AN15),AN15>SETTINGS!$B$14),"STUCK in onboarding","")))
A16: 15 | B16: UPK2-DV-003 | C16: Ink n Bliss | D16: Digital & Visual Arts | E16: DV-CALLIGRAPHY-STATIONERY | F16: Mumbai | G16: B | H16: P0 | J16: Personal 1:1 email from founder/team to published business email | K16: https://www.inknbliss.com/contact | L16: W0 Pilot | AH16: =IF(AND(B16="",C16=""),"",IF(AND(X16<>"",Y16<>"",Z16<>"",AA16<>"",AB16="Y"),"YES","no")) | AI16: =IF(AH16="YES",MAX(X16,Y16,Z16,AA16),"") | AJ16: =IF(AND(B16="",C16=""),"",IF(OR(S16="Not interested",S16="Opt-out / do not contact"),"X Declined / suppressed",IF(S16="Bounced / undeliverable","X Bounced — research",IF(AC16<>"","13 Transacting",IF(AH16="YES","12 ACTIVATED",IF(Z16<>"","11 Listing live",IF(Y16<>"","10 Profile complete",IF(X16<>"","9 Approved",IF(W16<>"","8 KYC submitted",IF(V16<>"","7 Registered",IF(T16<>"","5 Interested",IF(R16<>"","4 Responded",IF(O16<>"","2 Contacted","1 Not yet contacted"))))))))))))) | AK16: =IF(AF16<>"",AF16,IF(OR(O16="",R16<>"",LEFT(AJ16,1)="X"),"",IF(Q16<>"","",IF(P16<>"",P16+SETTINGS!$B$4,O16+SETTINGS!$B$3)))) | AL16: =IF(AJ16="","",IF(LEFT(AJ16,1)="X","None — do not contact",IF(AJ16="1 Not yet contacted","Verify route today, then send M1",IF(AND(R16="",Q16<>""),"Sequence complete — no contact before "&TEXT(Q16+SETTINGS!$B$5,"yyyy-mm-dd"),IF(AND(R16="",P16<>""),"Send final note (M4)",IF(R16="","Send follow-up (M2)",IF(AJ16="12 ACTIVATED","7-day check-in; consent & referral soft ask",IF(AJ16="13 Transacting","Repeat-activity support","Onboarding: move to next stage (see playbook §6)")))))))) | AM16: =IF(ISNUMBER(AK16),IF(AK16<=TODAY(),"DUE",""),"") | AN16: =IF(COUNT(O16,P16,Q16,R16,T16,V16,W16,X16,Y16,Z16,AA16,AC16)=0,"",TODAY()-MAX(O16,P16,Q16,R16,T16,V16,W16,X16,Y16,Z16,AA16,AC16)) | AO16: =IF(AJ16="","",IF(AND(T16<>"",U16<>"Active (verified)"),"GST: escalate (no tax advice)",IF(AND(IFERROR(VALUE(LEFT(AJ16,2)),0)>=5,AH16<>"YES",ISNUMBER(AN16),AN16>SETTINGS!$B$14),"STUCK in onboarding","")))
A17: 16 | B17: UPK2-BM-277 | C17: Ram Kumar Mehandi | D17: Beauty & Makeup | E17: BM-MEHENDI | F17: Delhi NCR | G17: A | H17: P0 | J17: Personal 1:1 email from founder/team to published business email | K17: https://ramkumarmehandi.com/landing/ | L17: W0 Pilot | AH17: =IF(AND(B17="",C17=""),"",IF(AND(X17<>"",Y17<>"",Z17<>"",AA17<>"",AB17="Y"),"YES","no")) | AI17: =IF(AH17="YES",MAX(X17,Y17,Z17,AA17),"") | AJ17: =IF(AND(B17="",C17=""),"",IF(OR(S17="Not interested",S17="Opt-out / do not contact"),"X Declined / suppressed",IF(S17="Bounced / undeliverable","X Bounced — research",IF(AC17<>"","13 Transacting",IF(AH17="YES","12 ACTIVATED",IF(Z17<>"","11 Listing live",IF(Y17<>"","10 Profile complete",IF(X17<>"","9 Approved",IF(W17<>"","8 KYC submitted",IF(V17<>"","7 Registered",IF(T17<>"","5 Interested",IF(R17<>"","4 Responded",IF(O17<>"","2 Contacted","1 Not yet contacted"))))))))))))) | AK17: =IF(AF17<>"",AF17,IF(OR(O17="",R17<>"",LEFT(AJ17,1)="X"),"",IF(Q17<>"","",IF(P17<>"",P17+SETTINGS!$B$4,O17+SETTINGS!$B$3)))) | AL17: =IF(AJ17="","",IF(LEFT(AJ17,1)="X","None — do not contact",IF(AJ17="1 Not yet contacted","Verify route today, then send M1",IF(AND(R17="",Q17<>""),"Sequence complete — no contact before "&TEXT(Q17+SETTINGS!$B$5,"yyyy-mm-dd"),IF(AND(R17="",P17<>""),"Send final note (M4)",IF(R17="","Send follow-up (M2)",IF(AJ17="12 ACTIVATED","7-day check-in; consent & referral soft ask",IF(AJ17="13 Transacting","Repeat-activity support","Onboarding: move to next stage (see playbook §6)")))))))) | AM17: =IF(ISNUMBER(AK17),IF(AK17<=TODAY(),"DUE",""),"") | AN17: =IF(COUNT(O17,P17,Q17,R17,T17,V17,W17,X17,Y17,Z17,AA17,AC17)=0,"",TODAY()-MAX(O17,P17,Q17,R17,T17,V17,W17,X17,Y17,Z17,AA17,AC17)) | AO17: =IF(AJ17="","",IF(AND(T17<>"",U17<>"Active (verified)"),"GST: escalate (no tax advice)",IF(AND(IFERROR(VALUE(LEFT(AJ17,2)),0)>=5,AH17<>"YES",ISNUMBER(AN17),AN17>SETTINGS!$B$14),"STUCK in onboarding","")))
A18: 17 | B18: UPK2-BM-163 | C18: Arun Mehandi | D18: Beauty & Makeup | E18: BM-MEHENDI | F18: Mumbai | G18: C | H18: P0 | J18: Personal 1:1 email from founder/team to published business email | K18: https://arunmehandi.com/ | L18: W0 Pilot | AH18: =IF(AND(B18="",C18=""),"",IF(AND(X18<>"",Y18<>"",Z18<>"",AA18<>"",AB18="Y"),"YES","no")) | AI18: =IF(AH18="YES",MAX(X18,Y18,Z18,AA18),"") | AJ18: =IF(AND(B18="",C18=""),"",IF(OR(S18="Not interested",S18="Opt-out / do not contact"),"X Declined / suppressed",IF(S18="Bounced / undeliverable","X Bounced — research",IF(AC18<>"","13 Transacting",IF(AH18="YES","12 ACTIVATED",IF(Z18<>"","11 Listing live",IF(Y18<>"","10 Profile complete",IF(X18<>"","9 Approved",IF(W18<>"","8 KYC submitted",IF(V18<>"","7 Registered",IF(T18<>"","5 Interested",IF(R18<>"","4 Responded",IF(O18<>"","2 Contacted","1 Not yet contacted"))))))))))))) | AK18: =IF(AF18<>"",AF18,IF(OR(O18="",R18<>"",LEFT(AJ18,1)="X"),"",IF(Q18<>"","",IF(P18<>"",P18+SETTINGS!$B$4,O18+SETTINGS!$B$3)))) | AL18: =IF(AJ18="","",IF(LEFT(AJ18,1)="X","None — do not contact",IF(AJ18="1 Not yet contacted","Verify route today, then send M1",IF(AND(R18="",Q18<>""),"Sequence complete — no contact before "&TEXT(Q18+SETTINGS!$B$5,"yyyy-mm-dd"),IF(AND(R18="",P18<>""),"Send final note (M4)",IF(R18="","Send follow-up (M2)",IF(AJ18="12 ACTIVATED","7-day check-in; consent & referral soft ask",IF(AJ18="13 Transacting","Repeat-activity support","Onboarding: move to next stage (see playbook §6)")))))))) | AM18: =IF(ISNUMBER(AK18),IF(AK18<=TODAY(),"DUE",""),"") | AN18: =IF(COUNT(O18,P18,Q18,R18,T18,V18,W18,X18,Y18,Z18,AA18,AC18)=0,"",TODAY()-MAX(O18,P18,Q18,R18,T18,V18,W18,X18,Y18,Z18,AA18,AC18)) | AO18: =IF(AJ18="","",IF(AND(T18<>"",U18<>"Active (verified)"),"GST: escalate (no tax advice)",IF(AND(IFERROR(VALUE(LEFT(AJ18,2)),0)>=5,AH18<>"YES",ISNUMBER(AN18),AN18>SETTINGS!$B$14),"STUCK in onboarding","")))
A19: 18 | B19: UPK2-BM-178 | C19: Himani Bhandula Makeup Artist | D19: Beauty & Makeup | E19: BM-INDEPENDENT-MUA | F19: Delhi NCR | G19: B | H19: P0 | J19: 1:1 message via own-website contact form | K19: https://himanibhandula.com/contact/ | L19: W0 Pilot | AH19: =IF(AND(B19="",C19=""),"",IF(AND(X19<>"",Y19<>"",Z19<>"",AA19<>"",AB19="Y"),"YES","no")) | AI19: =IF(AH19="YES",MAX(X19,Y19,Z19,AA19),"") | AJ19: =IF(AND(B19="",C19=""),"",IF(OR(S19="Not interested",S19="Opt-out / do not contact"),"X Declined / suppressed",IF(S19="Bounced / undeliverable","X Bounced — research",IF(AC19<>"","13 Transacting",IF(AH19="YES","12 ACTIVATED",IF(Z19<>"","11 Listing live",IF(Y19<>"","10 Profile complete",IF(X19<>"","9 Approved",IF(W19<>"","8 KYC submitted",IF(V19<>"","7 Registered",IF(T19<>"","5 Interested",IF(R19<>"","4 Responded",IF(O19<>"","2 Contacted","1 Not yet contacted"))))))))))))) | AK19: =IF(AF19<>"",AF19,IF(OR(O19="",R19<>"",LEFT(AJ19,1)="X"),"",IF(Q19<>"","",IF(P19<>"",P19+SETTINGS!$B$4,O19+SETTINGS!$B$3)))) | AL19: =IF(AJ19="","",IF(LEFT(AJ19,1)="X","None — do not contact",IF(AJ19="1 Not yet contacted","Verify route today, then send M1",IF(AND(R19="",Q19<>""),"Sequence complete — no contact before "&TEXT(Q19+SETTINGS!$B$5,"yyyy-mm-dd"),IF(AND(R19="",P19<>""),"Send final note (M4)",IF(R19="","Send follow-up (M2)",IF(AJ19="12 ACTIVATED","7-day check-in; consent & referral soft ask",IF(AJ19="13 Transacting","Repeat-activity support","Onboarding: move to next stage (see playbook §6)")))))))) | AM19: =IF(ISNUMBER(AK19),IF(AK19<=TODAY(),"DUE",""),"") | AN19: =IF(COUNT(O19,P19,Q19,R19,T19,V19,W19,X19,Y19,Z19,AA19,AC19)=0,"",TODAY()-MAX(O19,P19,Q19,R19,T19,V19,W19,X19,Y19,Z19,AA19,AC19)) | AO19: =IF(AJ19="","",IF(AND(T19<>"",U19<>"Active (verified)"),"GST: escalate (no tax advice)",IF(AND(IFERROR(VALUE(LEFT(AJ19,2)),0)>=5,AH19<>"YES",ISNUMBER(AN19),AN19>SETTINGS!$B$14),"STUCK in onboarding","")))
A20: 19 | B20: UPK2-BM-208 | C20: Roopali Talwar Makeup Artist | D20: Beauty & Makeup | E20: BM-INDEPENDENT-MUA | F20: Delhi NCR | G20: B | H20: P0 | J20: 1:1 message via own-website contact form | K20: https://roopalitalwar.com/ | L20: W0 Pilot | AH20: =IF(AND(B20="",C20=""),"",IF(AND(X20<>"",Y20<>"",Z20<>"",AA20<>"",AB20="Y"),"YES","no")) | AI20: =IF(AH20="YES",MAX(X20,Y20,Z20,AA20),"") | AJ20: =IF(AND(B20="",C20=""),"",IF(OR(S20="Not interested",S20="Opt-out / do not contact"),"X Declined / suppressed",IF(S20="Bounced / undeliverable","X Bounced — research",IF(AC20<>"","13 Transacting",IF(AH20="YES","12 ACTIVATED",IF(Z20<>"","11 Listing live",IF(Y20<>"","10 Profile complete",IF(X20<>"","9 Approved",IF(W20<>"","8 KYC submitted",IF(V20<>"","7 Registered",IF(T20<>"","5 Interested",IF(R20<>"","4 Responded",IF(O20<>"","2 Contacted","1 Not yet contacted"))))))))))))) | AK20: =IF(AF20<>"",AF20,IF(OR(O20="",R20<>"",LEFT(AJ20,1)="X"),"",IF(Q20<>"","",IF(P20<>"",P20+SETTINGS!$B$4,O20+SETTINGS!$B$3)))) | AL20: =IF(AJ20="","",IF(LEFT(AJ20,1)="X","None — do not contact",IF(AJ20="1 Not yet contacted","Verify route today, then send M1",IF(AND(R20="",Q20<>""),"Sequence complete — no contact before "&TEXT(Q20+SETTINGS!$B$5,"yyyy-mm-dd"),IF(AND(R20="",P20<>""),"Send final note (M4)",IF(R20="","Send follow-up (M2)",IF(AJ20="12 ACTIVATED","7-day check-in; consent & referral soft ask",IF(AJ20="13 Transacting","Repeat-activity support","Onboarding: move to next stage (see playbook §6)")))))))) | AM20: =IF(ISNUMBER(AK20),IF(AK20<=TODAY(),"DUE",""),"") | AN20: =IF(COUNT(O20,P20,Q20,R20,T20,V20,W20,X20,Y20,Z20,AA20,AC20)=0,"",TODAY()-MAX(O20,P20,Q20,R20,T20,V20,W20,X20,Y20,Z20,AA20,AC20)) | AO20: =IF(AJ20="","",IF(AND(T20<>"",U20<>"Active (verified)"),"GST: escalate (no tax advice)",IF(AND(IFERROR(VALUE(LEFT(AJ20,2)),0)>=5,AH20<>"YES",ISNUMBER(AN20),AN20>SETTINGS!$B$14),"STUCK in onboarding","")))
A21: 20 | B21: UPK2-LM-219 | C21: 7 Vows Stories | D21: Lens & Motion | E21: LM-WEDDING | F21: Delhi NCR | G21: A | H21: P0 | J21: Personal 1:1 email from founder/team to published business email | K21: https://www.7vowsstories.com/ | L21: W0 Pilot | AH21: =IF(AND(B21="",C21=""),"",IF(AND(X21<>"",Y21<>"",Z21<>"",AA21<>"",AB21="Y"),"YES","no")) | AI21: =IF(AH21="YES",MAX(X21,Y21,Z21,AA21),"") | AJ21: =IF(AND(B21="",C21=""),"",IF(OR(S21="Not interested",S21="Opt-out / do not contact"),"X Declined / suppressed",IF(S21="Bounced / undeliverable","X Bounced — research",IF(AC21<>"","13 Transacting",IF(AH21="YES","12 ACTIVATED",IF(Z21<>"","11 Listing live",IF(Y21<>"","10 Profile complete",IF(X21<>"","9 Approved",IF(W21<>"","8 KYC submitted",IF(V21<>"","7 Registered",IF(T21<>"","5 Interested",IF(R21<>"","4 Responded",IF(O21<>"","2 Contacted","1 Not yet contacted"))))))))))))) | AK21: =IF(AF21<>"",AF21,IF(OR(O21="",R21<>"",LEFT(AJ21,1)="X"),"",IF(Q21<>"","",IF(P21<>"",P21+SETTINGS!$B$4,O21+SETTINGS!$B$3)))) | AL21: =IF(AJ21="","",IF(LEFT(AJ21,1)="X","None — do not contact",IF(AJ21="1 Not yet contacted","Verify route today, then send M1",IF(AND(R21="",Q21<>""),"Sequence complete — no contact before "&TEXT(Q21+SETTINGS!$B$5,"yyyy-mm-dd"),IF(AND(R21="",P21<>""),"Send final note (M4)",IF(R21="","Send follow-up (M2)",IF(AJ21="12 ACTIVATED","7-day check-in; consent & referral soft ask",IF(AJ21="13 Transacting","Repeat-activity support","Onboarding: move to next stage (see playbook §6)")))))))) | AM21: =IF(ISNUMBER(AK21),IF(AK21<=TODAY(),"DUE",""),"") | AN21: =IF(COUNT(O21,P21,Q21,R21,T21,V21,W21,X21,Y21,Z21,AA21,AC21)=0,"",TODAY()-MAX(O21,P21,Q21,R21,T21,V21,W21,X21,Y21,Z21,AA21,AC21)) | AO21: =IF(AJ21="","",IF(AND(T21<>"",U21<>"Active (verified)"),"GST: escalate (no tax advice)",IF(AND(IFERROR(VALUE(LEFT(AJ21,2)),0)>=5,AH21<>"YES",ISNUMBER(AN21),AN21>SETTINGS!$B$14),"STUCK in onboarding","")))
A22: 21 | B22: UPK2-LM-208 | C22: Photomist | D22: Lens & Motion | E22: LM-WEDDING | F22: Mumbai | G22: B | H22: P0 | J22: Personal 1:1 email from founder/team to published business email | K22: https://www.photomist.in/ | L22: W0 Pilot | AH22: =IF(AND(B22="",C22=""),"",IF(AND(X22<>"",Y22<>"",Z22<>"",AA22<>"",AB22="Y"),"YES","no")) | AI22: =IF(AH22="YES",MAX(X22,Y22,Z22,AA22),"") | AJ22: =IF(AND(B22="",C22=""),"",IF(OR(S22="Not interested",S22="Opt-out / do not contact"),"X Declined / suppressed",IF(S22="Bounced / undeliverable","X Bounced — research",IF(AC22<>"","13 Transacting",IF(AH22="YES","12 ACTIVATED",IF(Z22<>"","11 Listing live",IF(Y22<>"","10 Profile complete",IF(X22<>"","9 Approved",IF(W22<>"","8 KYC submitted",IF(V22<>"","7 Registered",IF(T22<>"","5 Interested",IF(R22<>"","4 Responded",IF(O22<>"","2 Contacted","1 Not yet contacted"))))))))))))) | AK22: =IF(AF22<>"",AF22,IF(OR(O22="",R22<>"",LEFT(AJ22,1)="X"),"",IF(Q22<>"","",IF(P22<>"",P22+SETTINGS!$B$4,O22+SETTINGS!$B$3)))) | AL22: =IF(AJ22="","",IF(LEFT(AJ22,1)="X","None — do not contact",IF(AJ22="1 Not yet contacted","Verify route today, then send M1",IF(AND(R22="",Q22<>""),"Sequence complete — no contact before "&TEXT(Q22+SETTINGS!$B$5,"yyyy-mm-dd"),IF(AND(R22="",P22<>""),"Send final note (M4)",IF(R22="","Send follow-up (M2)",IF(AJ22="12 ACTIVATED","7-day check-in; consent & referral soft ask",IF(AJ22="13 Transacting","Repeat-activity support","Onboarding: move to next stage (see playbook §6)")))))))) | AM22: =IF(ISNUMBER(AK22),IF(AK22<=TODAY(),"DUE",""),"") | AN22: =IF(COUNT(O22,P22,Q22,R22,T22,V22,W22,X22,Y22,Z22,AA22,AC22)=0,"",TODAY()-MAX(O22,P22,Q22,R22,T22,V22,W22,X22,Y22,Z22,AA22,AC22)) | AO22: =IF(AJ22="","",IF(AND(T22<>"",U22<>"Active (verified)"),"GST: escalate (no tax advice)",IF(AND(IFERROR(VALUE(LEFT(AJ22,2)),0)>=5,AH22<>"YES",ISNUMBER(AN22),AN22>SETTINGS!$B$14),"STUCK in onboarding","")))
A23: 22 | B23: UPK2-LM-225 | C23: A.Rrajani Photography | D23: Lens & Motion | E23: LM-COMMERCIAL-FASHION | F23: Mumbai | G23: C | H23: P0 | I23: under-discovered | J23: Personal 1:1 email from founder/team to published business email | K23: https://www.a-rrajani.com/contact-andheri-mumbai/ | L23: W0 Pilot | AH23: =IF(AND(B23="",C23=""),"",IF(AND(X23<>"",Y23<>"",Z23<>"",AA23<>"",AB23="Y"),"YES","no")) | AI23: =IF(AH23="YES",MAX(X23,Y23,Z23,AA23),"") | AJ23: =IF(AND(B23="",C23=""),"",IF(OR(S23="Not interested",S23="Opt-out / do not contact"),"X Declined / suppressed",IF(S23="Bounced / undeliverable","X Bounced — research",IF(AC23<>"","13 Transacting",IF(AH23="YES","12 ACTIVATED",IF(Z23<>"","11 Listing live",IF(Y23<>"","10 Profile complete",IF(X23<>"","9 Approved",IF(W23<>"","8 KYC submitted",IF(V23<>"","7 Registered",IF(T23<>"","5 Interested",IF(R23<>"","4 Responded",IF(O23<>"","2 Contacted","1 Not yet contacted"))))))))))))) | AK23: =IF(AF23<>"",AF23,IF(OR(O23="",R23<>"",LEFT(AJ23,1)="X"),"",IF(Q23<>"","",IF(P23<>"",P23+SETTINGS!$B$4,O23+SETTINGS!$B$3)))) | AL23: =IF(AJ23="","",IF(LEFT(AJ23,1)="X","None — do not contact",IF(AJ23="1 Not yet contacted","Verify route today, then send M1",IF(AND(R23="",Q23<>""),"Sequence complete — no contact before "&TEXT(Q23+SETTINGS!$B$5,"yyyy-mm-dd"),IF(AND(R23="",P23<>""),"Send final note (M4)",IF(R23="","Send follow-up (M2)",IF(AJ23="12 ACTIVATED","7-day check-in; consent & referral soft ask",IF(AJ23="13 Transacting","Repeat-activity support","Onboarding: move to next stage (see playbook §6)")))))))) | AM23: =IF(ISNUMBER(AK23),IF(AK23<=TODAY(),"DUE",""),"") | AN23: =IF(COUNT(O23,P23,Q23,R23,T23,V23,W23,X23,Y23,Z23,AA23,AC23)=0,"",TODAY()-MAX(O23,P23,Q23,R23,T23,V23,W23,X23,Y23,Z23,AA23,AC23)) | AO23: =IF(AJ23="","",IF(AND(T23<>"",U23<>"Active (verified)"),"GST: escalate (no tax advice)",IF(AND(IFERROR(VALUE(LEFT(AJ23,2)),0)>=5,AH23<>"YES",ISNUMBER(AN23),AN23>SETTINGS!$B$14),"STUCK in onboarding","")))
A24: 23 | B24: UPK2-LM-279 | C24: Jignesh Jhaveri | D24: Lens & Motion | E24: LM-COMMERCIAL-FASHION | F24: Mumbai | G24: C | H24: P0 | I24: under-discovered | J24: Personal 1:1 email from founder/team to published business email | K24: https://www.jigneshjhaveri.com/contact | L24: W0 Pilot | AH24: =IF(AND(B24="",C24=""),"",IF(AND(X24<>"",Y24<>"",Z24<>"",AA24<>"",AB24="Y"),"YES","no")) | AI24: =IF(AH24="YES",MAX(X24,Y24,Z24,AA24),"") | AJ24: =IF(AND(B24="",C24=""),"",IF(OR(S24="Not interested",S24="Opt-out / do not contact"),"X Declined / suppressed",IF(S24="Bounced / undeliverable","X Bounced — research",IF(AC24<>"","13 Transacting",IF(AH24="YES","12 ACTIVATED",IF(Z24<>"","11 Listing live",IF(Y24<>"","10 Profile complete",IF(X24<>"","9 Approved",IF(W24<>"","8 KYC submitted",IF(V24<>"","7 Registered",IF(T24<>"","5 Interested",IF(R24<>"","4 Responded",IF(O24<>"","2 Contacted","1 Not yet contacted"))))))))))))) | AK24: =IF(AF24<>"",AF24,IF(OR(O24="",R24<>"",LEFT(AJ24,1)="X"),"",IF(Q24<>"","",IF(P24<>"",P24+SETTINGS!$B$4,O24+SETTINGS!$B$3)))) | AL24: =IF(AJ24="","",IF(LEFT(AJ24,1)="X","None — do not contact",IF(AJ24="1 Not yet contacted","Verify route today, then send M1",IF(AND(R24="",Q24<>""),"Sequence complete — no contact before "&TEXT(Q24+SETTINGS!$B$5,"yyyy-mm-dd"),IF(AND(R24="",P24<>""),"Send final note (M4)",IF(R24="","Send follow-up (M2)",IF(AJ24="12 ACTIVATED","7-day check-in; consent & referral soft ask",IF(AJ24="13 Transacting","Repeat-activity support","Onboarding: move to next stage (see playbook §6)")))))))) | AM24: =IF(ISNUMBER(AK24),IF(AK24<=TODAY(),"DUE",""),"") | AN24: =IF(COUNT(O24,P24,Q24,R24,T24,V24,W24,X24,Y24,Z24,AA24,AC24)=0,"",TODAY()-MAX(O24,P24,Q24,R24,T24,V24,W24,X24,Y24,Z24,AA24,AC24)) | AO24: =IF(AJ24="","",IF(AND(T24<>"",U24<>"Active (verified)"),"GST: escalate (no tax advice)",IF(AND(IFERROR(VALUE(LEFT(AJ24,2)),0)>=5,AH24<>"YES",ISNUMBER(AN24),AN24>SETTINGS!$B$14),"STUCK in onboarding","")))
A25: 24 | B25: UPK2-CM-046 | C25: Amol Soni | D25: Content & Media | E25: CM-EMCEE-HOST | F25: Mumbai | G25: A | H25: P0 | J25: Personal 1:1 email from founder/team to published business email | K25: https://www.entertaineramolsoni.com/ | L25: W0 Pilot | AH25: =IF(AND(B25="",C25=""),"",IF(AND(X25<>"",Y25<>"",Z25<>"",AA25<>"",AB25="Y"),"YES","no")) | AI25: =IF(AH25="YES",MAX(X25,Y25,Z25,AA25),"") | AJ25: =IF(AND(B25="",C25=""),"",IF(OR(S25="Not interested",S25="Opt-out / do not contact"),"X Declined / suppressed",IF(S25="Bounced / undeliverable","X Bounced — research",IF(AC25<>"","13 Transacting",IF(AH25="YES","12 ACTIVATED",IF(Z25<>"","11 Listing live",IF(Y25<>"","10 Profile complete",IF(X25<>"","9 Approved",IF(W25<>"","8 KYC submitted",IF(V25<>"","7 Registered",IF(T25<>"","5 Interested",IF(R25<>"","4 Responded",IF(O25<>"","2 Contacted","1 Not yet contacted"))))))))))))) | AK25: =IF(AF25<>"",AF25,IF(OR(O25="",R25<>"",LEFT(AJ25,1)="X"),"",IF(Q25<>"","",IF(P25<>"",P25+SETTINGS!$B$4,O25+SETTINGS!$B$3)))) | AL25: =IF(AJ25="","",IF(LEFT(AJ25,1)="X","None — do not contact",IF(AJ25="1 Not yet contacted","Verify route today, then send M1",IF(AND(R25="",Q25<>""),"Sequence complete — no contact before "&TEXT(Q25+SETTINGS!$B$5,"yyyy-mm-dd"),IF(AND(R25="",P25<>""),"Send final note (M4)",IF(R25="","Send follow-up (M2)",IF(AJ25="12 ACTIVATED","7-day check-in; consent & referral soft ask",IF(AJ25="13 Transacting","Repeat-activity support","Onboarding: move to next stage (see playbook §6)")))))))) | AM25: =IF(ISNUMBER(AK25),IF(AK25<=TODAY(),"DUE",""),"") | AN25: =IF(COUNT(O25,P25,Q25,R25,T25,V25,W25,X25,Y25,Z25,AA25,AC25)=0,"",TODAY()-MAX(O25,P25,Q25,R25,T25,V25,W25,X25,Y25,Z25,AA25,AC25)) | AO25: =IF(AJ25="","",IF(AND(T25<>"",U25<>"Active (verified)"),"GST: escalate (no tax advice)",IF(AND(IFERROR(VALUE(LEFT(AJ25,2)),0)>=5,AH25<>"YES",ISNUMBER(AN25),AN25>SETTINGS!$B$14),"STUCK in onboarding","")))
A26: 25 | B26: UPK2-CM-044 | C26: Sagar Duggal | D26: Content & Media | E26: CM-EMCEE-HOST | F26: Delhi NCR | G26: C | H26: P0 | J26: Personal 1:1 email from founder/team to published business email | K26: https://talkativesagar.com/ | L26: W0 Pilot | AH26: =IF(AND(B26="",C26=""),"",IF(AND(X26<>"",Y26<>"",Z26<>"",AA26<>"",AB26="Y"),"YES","no")) | AI26: =IF(AH26="YES",MAX(X26,Y26,Z26,AA26),"") | AJ26: =IF(AND(B26="",C26=""),"",IF(OR(S26="Not interested",S26="Opt-out / do not contact"),"X Declined / suppressed",IF(S26="Bounced / undeliverable","X Bounced — research",IF(AC26<>"","13 Transacting",IF(AH26="YES","12 ACTIVATED",IF(Z26<>"","11 Listing live",IF(Y26<>"","10 Profile complete",IF(X26<>"","9 Approved",IF(W26<>"","8 KYC submitted",IF(V26<>"","7 Registered",IF(T26<>"","5 Interested",IF(R26<>"","4 Responded",IF(O26<>"","2 Contacted","1 Not yet contacted"))))))))))))) | AK26: =IF(AF26<>"",AF26,IF(OR(O26="",R26<>"",LEFT(AJ26,1)="X"),"",IF(Q26<>"","",IF(P26<>"",P26+SETTINGS!$B$4,O26+SETTINGS!$B$3)))) | AL26: =IF(AJ26="","",IF(LEFT(AJ26,1)="X","None — do not contact",IF(AJ26="1 Not yet contacted","Verify route today, then send M1",IF(AND(R26="",Q26<>""),"Sequence complete — no contact before "&TEXT(Q26+SETTINGS!$B$5,"yyyy-mm-dd"),IF(AND(R26="",P26<>""),"Send final note (M4)",IF(R26="","Send follow-up (M2)",IF(AJ26="12 ACTIVATED","7-day check-in; consent & referral soft ask",IF(AJ26="13 Transacting","Repeat-activity support","Onboarding: move to next stage (see playbook §6)")))))))) | AM26: =IF(ISNUMBER(AK26),IF(AK26<=TODAY(),"DUE",""),"") | AN26: =IF(COUNT(O26,P26,Q26,R26,T26,V26,W26,X26,Y26,Z26,AA26,AC26)=0,"",TODAY()-MAX(O26,P26,Q26,R26,T26,V26,W26,X26,Y26,Z26,AA26,AC26)) | AO26: =IF(AJ26="","",IF(AND(T26<>"",U26<>"Active (verified)"),"GST: escalate (no tax advice)",IF(AND(IFERROR(VALUE(LEFT(AJ26,2)),0)>=5,AH26<>"YES",ISNUMBER(AN26),AN26>SETTINGS!$B$14),"STUCK in onboarding","")))
A27: 26 | B27: UPK2-FL-171 | C27: Aseem Kapoor | D27: Fashion & Lifestyle | E27: FL-OCCASION-BRIDAL | F27: Delhi NCR | G27: A | H27: P0 | I27: stockist-listed|large catalogue | J27: Personal 1:1 email from founder/team to published business email | K27: https://aseemkapoor.com/pages/contact | L27: W1 Founding cohort | AH27: =IF(AND(B27="",C27=""),"",IF(AND(X27<>"",Y27<>"",Z27<>"",AA27<>"",AB27="Y"),"YES","no")) | AI27: =IF(AH27="YES",MAX(X27,Y27,Z27,AA27),"") | AJ27: =IF(AND(B27="",C27=""),"",IF(OR(S27="Not interested",S27="Opt-out / do not contact"),"X Declined / suppressed",IF(S27="Bounced / undeliverable","X Bounced — research",IF(AC27<>"","13 Transacting",IF(AH27="YES","12 ACTIVATED",IF(Z27<>"","11 Listing live",IF(Y27<>"","10 Profile complete",IF(X27<>"","9 Approved",IF(W27<>"","8 KYC submitted",IF(V27<>"","7 Registered",IF(T27<>"","5 Interested",IF(R27<>"","4 Responded",IF(O27<>"","2 Contacted","1 Not yet contacted"))))))))))))) | AK27: =IF(AF27<>"",AF27,IF(OR(O27="",R27<>"",LEFT(AJ27,1)="X"),"",IF(Q27<>"","",IF(P27<>"",P27+SETTINGS!$B$4,O27+SETTINGS!$B$3)))) | AL27: =IF(AJ27="","",IF(LEFT(AJ27,1)="X","None — do not contact",IF(AJ27="1 Not yet contacted","Verify route today, then send M1",IF(AND(R27="",Q27<>""),"Sequence complete — no contact before "&TEXT(Q27+SETTINGS!$B$5,"yyyy-mm-dd"),IF(AND(R27="",P27<>""),"Send final note (M4)",IF(R27="","Send follow-up (M2)",IF(AJ27="12 ACTIVATED","7-day check-in; consent & referral soft ask",IF(AJ27="13 Transacting","Repeat-activity support","Onboarding: move to next stage (see playbook §6)")))))))) | AM27: =IF(ISNUMBER(AK27),IF(AK27<=TODAY(),"DUE",""),"") | AN27: =IF(COUNT(O27,P27,Q27,R27,T27,V27,W27,X27,Y27,Z27,AA27,AC27)=0,"",TODAY()-MAX(O27,P27,Q27,R27,T27,V27,W27,X27,Y27,Z27,AA27,AC27)) | AO27: =IF(AJ27="","",IF(AND(T27<>"",U27<>"Active (verified)"),"GST: escalate (no tax advice)",IF(AND(IFERROR(VALUE(LEFT(AJ27,2)),0)>=5,AH27<>"YES",ISNUMBER(AN27),AN27>SETTINGS!$B$14),"STUCK in onboarding","")))
A28: 27 | B28: UPK2-FL-256 | C28: Atbw | D28: Fashion & Lifestyle | E28: FL-CONTEMPORARY | F28: Delhi NCR | G28: A | H28: P0 | I28: stockist-listed | J28: Personal 1:1 email from founder/team to published business email | K28: https://atbw.shop/collections/the-artists-notebook | L28: W1 Founding cohort | AH28: =IF(AND(B28="",C28=""),"",IF(AND(X28<>"",Y28<>"",Z28<>"",AA28<>"",AB28="Y"),"YES","no")) | AI28: =IF(AH28="YES",MAX(X28,Y28,Z28,AA28),"") | AJ28: =IF(AND(B28="",C28=""),"",IF(OR(S28="Not interested",S28="Opt-out / do not contact"),"X Declined / suppressed",IF(S28="Bounced / undeliverable","X Bounced — research",IF(AC28<>"","13 Transacting",IF(AH28="YES","12 ACTIVATED",IF(Z28<>"","11 Listing live",IF(Y28<>"","10 Profile complete",IF(X28<>"","9 Approved",IF(W28<>"","8 KYC submitted",IF(V28<>"","7 Registered",IF(T28<>"","5 Interested",IF(R28<>"","4 Responded",IF(O28<>"","2 Contacted","1 Not yet contacted"))))))))))))) | AK28: =IF(AF28<>"",AF28,IF(OR(O28="",R28<>"",LEFT(AJ28,1)="X"),"",IF(Q28<>"","",IF(P28<>"",P28+SETTINGS!$B$4,O28+SETTINGS!$B$3)))) | AL28: =IF(AJ28="","",IF(LEFT(AJ28,1)="X","None — do not contact",IF(AJ28="1 Not yet contacted","Verify route today, then send M1",IF(AND(R28="",Q28<>""),"Sequence complete — no contact before "&TEXT(Q28+SETTINGS!$B$5,"yyyy-mm-dd"),IF(AND(R28="",P28<>""),"Send final note (M4)",IF(R28="","Send follow-up (M2)",IF(AJ28="12 ACTIVATED","7-day check-in; consent & referral soft ask",IF(AJ28="13 Transacting","Repeat-activity support","Onboarding: move to next stage (see playbook §6)")))))))) | AM28: =IF(ISNUMBER(AK28),IF(AK28<=TODAY(),"DUE",""),"") | AN28: =IF(COUNT(O28,P28,Q28,R28,T28,V28,W28,X28,Y28,Z28,AA28,AC28)=0,"",TODAY()-MAX(O28,P28,Q28,R28,T28,V28,W28,X28,Y28,Z28,AA28,AC28)) | AO28: =IF(AJ28="","",IF(AND(T28<>"",U28<>"Active (verified)"),"GST: escalate (no tax advice)",IF(AND(IFERROR(VALUE(LEFT(AJ28,2)),0)>=5,AH28<>"YES",ISNUMBER(AN28),AN28>SETTINGS!$B$14),"STUCK in onboarding","")))
A29: 28 | B29: UPK2-FL-261 | C29: Jodi | D29: Fashion & Lifestyle | E29: FL-OCCASION-BRIDAL | F29: Bengaluru | G29: B | H29: P0 | I29: stockist-listed | J29: Personal 1:1 email from founder/team to published business email | K29: https://jodistudio.com/contact | L29: W1 Founding cohort | AH29: =IF(AND(B29="",C29=""),"",IF(AND(X29<>"",Y29<>"",Z29<>"",AA29<>"",AB29="Y"),"YES","no")) | AI29: =IF(AH29="YES",MAX(X29,Y29,Z29,AA29),"") | AJ29: =IF(AND(B29="",C29=""),"",IF(OR(S29="Not interested",S29="Opt-out / do not contact"),"X Declined / suppressed",IF(S29="Bounced / undeliverable","X Bounced — research",IF(AC29<>"","13 Transacting",IF(AH29="YES","12 ACTIVATED",IF(Z29<>"","11 Listing live",IF(Y29<>"","10 Profile complete",IF(X29<>"","9 Approved",IF(W29<>"","8 KYC submitted",IF(V29<>"","7 Registered",IF(T29<>"","5 Interested",IF(R29<>"","4 Responded",IF(O29<>"","2 Contacted","1 Not yet contacted"))))))))))))) | AK29: =IF(AF29<>"",AF29,IF(OR(O29="",R29<>"",LEFT(AJ29,1)="X"),"",IF(Q29<>"","",IF(P29<>"",P29+SETTINGS!$B$4,O29+SETTINGS!$B$3)))) | AL29: =IF(AJ29="","",IF(LEFT(AJ29,1)="X","None — do not contact",IF(AJ29="1 Not yet contacted","Verify route today, then send M1",IF(AND(R29="",Q29<>""),"Sequence complete — no contact before "&TEXT(Q29+SETTINGS!$B$5,"yyyy-mm-dd"),IF(AND(R29="",P29<>""),"Send final note (M4)",IF(R29="","Send follow-up (M2)",IF(AJ29="12 ACTIVATED","7-day check-in; consent & referral soft ask",IF(AJ29="13 Transacting","Repeat-activity support","Onboarding: move to next stage (see playbook §6)")))))))) | AM29: =IF(ISNUMBER(AK29),IF(AK29<=TODAY(),"DUE",""),"") | AN29: =IF(COUNT(O29,P29,Q29,R29,T29,V29,W29,X29,Y29,Z29,AA29,AC29)=0,"",TODAY()-MAX(O29,P29,Q29,R29,T29,V29,W29,X29,Y29,Z29,AA29,AC29)) | AO29: =IF(AJ29="","",IF(AND(T29<>"",U29<>"Active (verified)"),"GST: escalate (no tax advice)",IF(AND(IFERROR(VALUE(LEFT(AJ29,2)),0)>=5,AH29<>"YES",ISNUMBER(AN29),AN29>SETTINGS!$B$14),"STUCK in onboarding","")))
A30: 29 | B30: UPK2-FL-267 | C30: Amisha Kothari | D30: Fashion & Lifestyle | E30: FL-CONTEMPORARY | F30: Mumbai | G30: B | H30: P0 | I30: stockist-listed | J30: Personal 1:1 email from founder/team to published business email | K30: https://amishakotharilabel.com/contact/ | L30: W1 Founding cohort | AH30: =IF(AND(B30="",C30=""),"",IF(AND(X30<>"",Y30<>"",Z30<>"",AA30<>"",AB30="Y"),"YES","no")) | AI30: =IF(AH30="YES",MAX(X30,Y30,Z30,AA30),"") | AJ30: =IF(AND(B30="",C30=""),"",IF(OR(S30="Not interested",S30="Opt-out / do not contact"),"X Declined / suppressed",IF(S30="Bounced / undeliverable","X Bounced — research",IF(AC30<>"","13 Transacting",IF(AH30="YES","12 ACTIVATED",IF(Z30<>"","11 Listing live",IF(Y30<>"","10 Profile complete",IF(X30<>"","9 Approved",IF(W30<>"","8 KYC submitted",IF(V30<>"","7 Registered",IF(T30<>"","5 Interested",IF(R30<>"","4 Responded",IF(O30<>"","2 Contacted","1 Not yet contacted"))))))))))))) | AK30: =IF(AF30<>"",AF30,IF(OR(O30="",R30<>"",LEFT(AJ30,1)="X"),"",IF(Q30<>"","",IF(P30<>"",P30+SETTINGS!$B$4,O30+SETTINGS!$B$3)))) | AL30: =IF(AJ30="","",IF(LEFT(AJ30,1)="X","None — do not contact",IF(AJ30="1 Not yet contacted","Verify route today, then send M1",IF(AND(R30="",Q30<>""),"Sequence complete — no contact before "&TEXT(Q30+SETTINGS!$B$5,"yyyy-mm-dd"),IF(AND(R30="",P30<>""),"Send final note (M4)",IF(R30="","Send follow-up (M2)",IF(AJ30="12 ACTIVATED","7-day check-in; consent & referral soft ask",IF(AJ30="13 Transacting","Repeat-activity support","Onboarding: move to next stage (see playbook §6)")))))))) | AM30: =IF(ISNUMBER(AK30),IF(AK30<=TODAY(),"DUE",""),"") | AN30: =IF(COUNT(O30,P30,Q30,R30,T30,V30,W30,X30,Y30,Z30,AA30,AC30)=0,"",TODAY()-MAX(O30,P30,Q30,R30,T30,V30,W30,X30,Y30,Z30,AA30,AC30)) | AO30: =IF(AJ30="","",IF(AND(T30<>"",U30<>"Active (verified)"),"GST: escalate (no tax advice)",IF(AND(IFERROR(VALUE(LEFT(AJ30,2)),0)>=5,AH30<>"YES",ISNUMBER(AN30),AN30>SETTINGS!$B$14),"STUCK in onboarding","")))
